Workbook

Sheet Test Plan
A1: Test Design Specification - Registration (EP, BVA) & Login (State Transition)
A2: Structured per ISTQB CTFL v4.0: test analysis (conditions) -> test design (coverage items, cases) -> test implementation (data, preconditions).
A4: 1. Identification
A5: Test objects | B5: Customer registration form: https://practicesoftwaretesting.com/auth/register Login page: https://practicesoftwaretesting.com/auth/login (Toolshop v5.0)
A6: Scope | B6: In: client-side and server-side field validation on registration (EP, BVA); authentication states, failed-attempt counter, lockout, unlock, TOTP and disabled-account behaviour on login (State Transition). Out: social login, forgot password, UI layout, accessibility, performance, security penetration, cross-browser.
A7: 2. Test basis
A8: Requirements | B8: _user-stories/sprint0/us-register.md and us-login.md (GitHub: testsmith-io/practice-software-testing). NOTE: us-register.md contains the login story text, so registration has no written acceptance criteria (see Open Questions Q1).
A9: Specification derived from code | B9: Because written requirements are incomplete, rules were taken from the published source (main branch, sprint5): - UI validators: sprint5/UI/src/app/auth/register/register.component.ts, login.component.ts - API rules: sprint5/API/app/Http/Requests/Customer/StoreCustomer.php - Lockout logic: sprint5/API/app/Services/UserService.php (MAX_LOGIN_ATTEMPTS = 3) - UI messages: sprint5/UI/src/assets/i18n/en.json The deployed site may differ from main; any mismatch is logged as an anomaly, not silently accepted.
A10: 3. Techniques & coverage criteria
A11: Equivalence Partitioning | B11: Sheet 'EP Analysis' -> 'TC - EP'. Coverage criterion: each valid and invalid partition exercised at least once. Valid partitions are combined in one case; invalid partitions are tested one per case (all other fields valid) to avoid defect masking.
A12: Boundary Value Analysis | B12: Sheet 'BVA Analysis' -> 'TC - BVA'. 2-value BVA (boundary + nearest neighbour across it) for length limits. 3-value BVA (boundary and both neighbours) for the high-risk age limits (18 and 75). Boundaries at 0 characters reuse EP cases rather than duplicating them.
A13: State Transition Testing | B13: Sheet 'STT Model' -> 'TC - STT'. Coverage: all states, all valid transitions (0-switch), selected invalid transitions (events rejected in Locked / Disabled states), plus one 1-switch sequence proving the counter resets after a successful login.
A14: 4. Environment & entry criteria
A15: Environment | B15: Chrome (latest), desktop, public demo site. Cases marked 'LOCAL' need a self-hosted Docker instance (they change shared admin data).
A16: Entry criteria | B16: Site reachable; demo data present (admin@practicesoftwaretesting.com / welcome01); tester has a TOTP authenticator app for TOTP cases.
A17: Date-dependent cases | B17: Age boundaries are calculated from TODAY in sheet 'Test Data' (re-opens with current values). Run them between 05:30 and 23:59 IST so the IST date equals the server (UTC) date.
A18: 5. Common preconditions
A19: PRE-R1 (Register) | B19: Logged out. Open /auth/register. Enter the Baseline Data below in every field except the one(s) named in 'Test Data'. Enter Country, Postcode and House number BEFORE Street/City/State (postcode lookup may auto-fill those three; overwrite if needed).
A20: Baseline Data | B20: First name: Asha | Last name: Patil | DOB: 1995-06-15 | Country: India | Postcode: 411018 | House number: 12 | Street: Station Road | City: Pune | State: Maharashtra | Phone: 9876543210 | Email: qa.<tc-id>.<run>@example.com (e.g. qa.tcbva02.r1@example.com - must be unique every run) | Password: Tq7#mLpz9
A21: PRE-L1 (Login) | B21: A customer account registered for THIS case only (never reuse a locked account), failed attempts = 0. Logged out on /auth/login. Wrong password used for failures: Wrong#123x.
A22: PRE-ADMIN | B22: Unlock / disable path: log in as admin@practicesoftwaretesting.com / welcome01 -> Users -> edit the test user -> set 'Failed login attempts' = 0 (unlock) or untick 'Enabled' (disable) -> Save -> log out.
A23: 6. Legend
A24: Priority (execution order) | B24: P1 = must run every cycle (core flow / high risk); P2 = run each release; P3 = run when time allows.
A25: Severity (impact if the case fails) | B25: Critical = security, legal (age) or core flow blocked; Major = wrong validation, bad data accepted; Minor = wording / usability. Per ISTQB, severity is formally a defect attribute; here it is the expected severity of a failure.
A26: Status | B26: Not Run / Pass / Fail / Blocked (drop-down on each TC sheet). 'Code review predicts FAIL' in Remarks = static analysis found a likely defect before execution.
A27: 7. Exit criteria | B27: 100% of P1 executed and passed or defects raised; all partitions, boundaries and valid transitions covered (see 'Summary'); open questions answered or accepted as risks.

Sheet Summary
A1: Execution & Coverage Summary (updates automatically from the Status column)
A3: Technique / sheet | B3: Total | C3: Not Run | D3: Pass | E3: Fail | F3: Blocked | G3: Executed % | H3: Pass rate (of executed) | I3: P1 | J3: P2 | K3: P3
A4: TC - EP | B4: =COUNTA('TC - EP'!A4:A200) -> 31 | C4: =COUNTIF('TC - EP'!L4:L200,"Not Run") -> 31 | D4: =COUNTIF('TC - EP'!L4:L200,"Pass") -> 0 | E4: =COUNTIF('TC - EP'!L4:L200,"Fail") -> 0 | F4: =COUNTIF('TC - EP'!L4:L200,"Blocked") -> 0 | G4: =IFERROR((B4-C4)/B4,0) -> 0 | H4: =IFERROR(D4/(D4+E4),0) -> 0 | I4: =COUNTIF('TC - EP'!I4:I200,"P1") -> 14 | J4: =COUNTIF('TC - EP'!I4:I200,"P2") -> 15 | K4: =COUNTIF('TC - EP'!I4:I200,"P3") -> 2
A5: TC - BVA | B5: =COUNTA('TC - BVA'!A4:A200) -> 37 | C5: =COUNTIF('TC - BVA'!L4:L200,"Not Run") -> 37 | D5: =COUNTIF('TC - BVA'!L4:L200,"Pass") -> 0 | E5: =COUNTIF('TC - BVA'!L4:L200,"Fail") -> 0 | F5: =COUNTIF('TC - BVA'!L4:L200,"Blocked") -> 0 | G5: =IFERROR((B5-C5)/B5,0) -> 0 | H5: =IFERROR(D5/(D5+E5),0) -> 0 | I5: =COUNTIF('TC - BVA'!I4:I200,"P1") -> 5 | J5: =COUNTIF('TC - BVA'!I4:I200,"P2") -> 15 | K5: =COUNTIF('TC - BVA'!I4:I200,"P3") -> 17
A6: TC - STT | B6: =COUNTA('TC - STT'!A4:A200) -> 19 | C6: =COUNTIF('TC - STT'!L4:L200,"Not Run") -> 19 | D6: =COUNTIF('TC - STT'!L4:L200,"Pass") -> 0 | E6: =COUNTIF('TC - STT'!L4:L200,"Fail") -> 0 | F6: =COUNTIF('TC - STT'!L4:L200,"Blocked") -> 0 | G6: =IFERROR((B6-C6)/B6,0) -> 0 | H6: =IFERROR(D6/(D6+E6),0) -> 0 | I6: =COUNTIF('TC - STT'!I4:I200,"P1") -> 10 | J6: =COUNTIF('TC - STT'!I4:I200,"P2") -> 4 | K6: =COUNTIF('TC - STT'!I4:I200,"P3") -> 5
A7: Total | B7: =SUM(B4:B6) -> 87 | C7: =SUM(C4:C6) -> 87 | D7: =SUM(D4:D6) -> 0 | E7: =SUM(E4:E6) -> 0 | F7: =SUM(F4:F6) -> 0 | G7: =IFERROR((B7-C7)/B7,0) -> 0 | H7: =IFERROR(D7/(D7+E7),0) -> 0 | I7: =SUM(I4:I6) -> 29 | J7: =SUM(J4:J6) -> 34 | K7: =SUM(K4:K6) -> 24
A9: Test-design coverage
A10: EP partitions covered | B10: =COUNTA('EP Analysis'!B4:B100) -> 40 | C10: All partitions mapped to at least one TC
A11: BVA boundaries analysed | B11: =COUNTA('BVA Analysis'!A4:A100) -> 20 | C11: 1 row (password max) not designable - Q6
A12: STT transitions covered | B12: =COUNTA('STT Model'!A34:A51) -> 18 | C12: All states 7/7; valid + key invalid transitions
A13: Open questions | B13: =COUNTA('[1]Open Questions'!A4:A100) -> 14 | C13: Resolve before sign-off
A14: Cases predicted to fail by code review | B14: =COUNTIF('TC - EP'!M4:M200,"*predicts FAIL*")+COUNTIF('TC - BVA'!M4:M200,"*predicts FAIL*")+COUNTIF('TC - STT'!M4:M200,"*predicts FAIL*") -> 4 | C14: See Q3, Q10

Sheet EP Analysis
A1: Equivalence Partitioning - Test Analysis (Registration)
A2: V = valid partition, I = invalid partition. One representative value per partition is sufficient by EP theory.
A3: Field | B3: Partition ID | C3: Partition | D3: V / I | E3: Representative value | F3: Rule (source) | G3: Covered by
A4: First name | B4: EP-FN-V1 | C4: Non-empty text | D4: V | E4: Asha | F4: UI required; API string max 40 | G4: TC-EP-01
A5: First name | B5: EP-FN-I1 | C5: Empty | D5: I | E5: (blank) | F5: UI required | G5: TC-EP-03
A6: First name | B6: EP-FN-I2 | C6: Whitespace only | D6: I | E6: 3 spaces | F6: API TrimStrings + required | G6: TC-EP-04
A7: First name | B7: EP-FN-I3 | C7: Contains superscript/subscript chars | D7: I | E7: Asha² | F7: API SubscriptSuperscriptRule | G7: TC-EP-05
A8: Last name | B8: EP-LN-V1 | C8: Non-empty text | D8: V | E8: Patil | F8: UI required; API max 20 | G8: TC-EP-01
A9: Last name | B9: EP-LN-I1 | C9: Empty | D9: I | E9: (blank) | F9: UI required | G9: TC-EP-06
A10: DOB format | B10: EP-DOB-V1 | C10: Real calendar date in YYYY-MM-DD | D10: V | E10: 1995-06-15 | F10: UI isoDate; API date_format:Y-m-d | G10: TC-EP-01
A11: DOB format | B11: EP-DOB-I1 | C11: Wrong format | D11: I | E11: 15-06-1995 | F11: UI isoDate | G11: TC-EP-07
A12: DOB format | B12: EP-DOB-I2 | C12: Correct format, non-existent date | D12: I | E12: 1995-02-30 | F12: UI isoDate (UTC check) | G12: TC-EP-08
A13: DOB format | B13: EP-DOB-I3 | C13: Empty | D13: I | E13: (blank) | F13: UI required | G13: TC-EP-09
A14: Age (from DOB) | B14: EP-AGE-I1 | C14: Under 18 | D14: I | E14: Age 10 (TD-27) | F14: API before: today-18y | G14: TC-EP-10
... A43: Password | B43: EP-PW-I6 | C43: Empty | D43: I | E43: (blank) | F43: UI required | G43: TC-EP-31

Sheet TC - EP
A1: Test Cases - Equivalence Partitioning - Registration
A2: Fill Actual result and Status during execution. Test data IDs (TD-xx) refer to sheet 'Test Data'.
A3: TC ID | B3: Test condition | C3: Coverage item | D3: Title | E3: Preconditions | F3: Test data | G3: Test steps | H3: Expected result | I3: Priority | J3: Severity | K3: Actual result | L3: Status | M3: Remarks
A4: TC-EP-01 | B4: Registration with all valid partitions | C4: All V1 partitions; EP-PC-V2 | D4: Register with valid data (country without postcode pattern) | E4: PRE-R1 | F4: Baseline Data (India / 411018); Email qa.tcep01.<run>@example.com | G4: 1. Complete PRE-R1. 2. Click Register. | H4: Registration succeeds; user is redirected to the Login page (/auth/login). New account can log in. | I4: P1 | J4: Critical | L4: Not Run
A5: TC-EP-02 | B5: Postcode matching country pattern | C5: EP-PC-V1 | D5: Register with Germany and a valid 5-digit postcode | E5: PRE-R1 | F5: Country: Germany; Postcode: 10115 | G5: 1. Complete PRE-R1. 2. Country / Postcode: enter Germany / 10115. 3. Click Register. | H5: Registration succeeds; user is redirected to the Login page (/auth/login). New account can log in. Also serves as BVA 5-digit boundary. | I5: P2 | J5: Major | L5: Not Run
A6: TC-EP-03 | B6: First name mandatory | C6: EP-FN-I1 | D6: Reject empty first name | E6: PRE-R1 | F6: First name: (blank) | G6: 1. Complete PRE-R1. 2. Leave First name empty. 3. Click Register. | H6: Form is not submitted / account not created. Stays on Register page. Error under the field: 'First name is required'. | I6: P1 | J6: Major | L6: Not Run
A7: TC-EP-04 | B7: First name not whitespace | C7: EP-FN-I2 | D7: Reject whitespace-only first name | E7: PRE-R1 | F7: First name: 3 spaces | G7: 1. Complete PRE-R1. 2. First name: enter 3 spaces. 3. Click Register. | H7: Account not created. Error stating first name is required. | I7: P2 | J7: Major | L7: Not Run | M7: UI 'required' does not trim; relies on server trimming.
A8: TC-EP-05 | B8: First name character set | C8: EP-FN-I3 | D8: Reject superscript characters in first name | E8: PRE-R1 | F8: First name: Asha² | G8: 1. Complete PRE-R1. 2. First name: enter Asha². 3. Click Register. | H8: Account not created. Stays on Register page. Server error shown at top of form stating first name must not contain subscript/superscript characters. | I8: P3 | J8: Minor | L8: Not Run
A9: TC-EP-06 | B9: Last name mandatory | C9: EP-LN-I1 | D9: Reject empty last name | E9: PRE-R1 | F9: Last name: (blank) | G9: 1. Complete PRE-R1. 2. Leave Last name empty. 3. Click Register. | H9: Form is not submitted / account not created. Stays on Register page. Error under the field: 'Last name is required'. | I9: P1 | J9: Major | L9: Not Run
A10: TC-EP-07 | B10: DOB format | C10: EP-DOB-I1 | D10: Reject DOB in DD-MM-YYYY | E10: PRE-R1 | F10: DOB: 15-06-1995 | G10: 1. Complete PRE-R1. 2. DOB: enter 15-06-1995. 3. Click Register. | H10: Form is not submitted / account not created. Stays on Register page. Error under the field: 'Please enter a valid date in YYYY-MM-DD format.'. | I10: P2 | J10: Major | L10: Not Run
A11: TC-EP-08 | B11: DOB is a real date | C11: EP-DOB-I2 | D11: Reject non-existent date | E11: PRE-R1 | F11: DOB: 1995-02-30 | G11: 1. Complete PRE-R1. 2. DOB: enter 1995-02-30. 3. Click Register. | H11: Form is not submitted / account not created. Stays on Register page. Error under the field: 'Please enter a valid date in YYYY-MM-DD format.'. | I11: P2 | J11: Major | L11: Not Run
A12: TC-EP-09 | B12: DOB mandatory | C12: EP-DOB-I3 | D12: Reject empty DOB | E12: PRE-R1 | F12: DOB: (blank) | G12: 1. Complete PRE-R1. 2. Leave DOB empty. 3. Click Register. | H12: Form is not submitted / account not created. Stays on Register page. Error under the field: 'Date of Birth is required'. | I12: P1 | J12: Major | L12: Not Run
A13: TC-EP-10 | B13: Minimum age | C13: EP-AGE-I1 | D13: Reject customer under 18 | E13: PRE-R1 | F13: DOB: TD-27 (age 10) | G13: 1. Complete PRE-R1. 2. DOB: enter TD-27. 3. Click Register. | H13: Account not created. Stays on Register page. Server error shown at top of form stating 'Customer must be 18 years old.'. | I13: P1 | J13: Critical | L13: Not Run | M13: Legal requirement.
A14: TC-EP-11 | B14: Maximum age | C14: EP-AGE-I2 | D14: Reject customer aged 75 or older | E14: PRE-R1 | F14: DOB: TD-28 (age 80) | G14: 1. Complete PRE-R1. 2. DOB: enter TD-28. 3. Click Register. | H14: Account not created. Stays on Register page. Server error shown at top of form stating 'Customer must be younger than 75 years old.'. | I14: P2 | J14: Major | L14: Not Run | M14: Code review predicts FAIL - see Q3.
A15: TC-EP-12 | B15: Country mandatory | C15: EP-CTY-I1 | D15: Reject when no country selected | E15: PRE-R1 | F15: Country: not selected | G15: 1. Complete PRE-R1 but leave Country on placeholder. 2. Click Register. | H15: Form is not submitted / account not created. Stays on Register page. Error under the field: 'Country is required'. | I15: P1 | J15: Major | L15: Not Run
A16: TC-EP-13 | B16: Postcode format per country | C16: EP-PC-I1 | D16: Reject postcode not matching Germany pattern | E16: PRE-R1 | F16: Country: Germany; Postcode: ABCDE | G16: 1. Complete PRE-R1. 2. Country / Postcode: enter Germany / ABCDE. 3. Click Register. | H16: Form is not submitted / account not created. Stays on Register page. Error under the field: 'Please enter a valid postal code for the selected country.'. | I16: P2 | J16: Major | L16: Not Run | M16: Error appears while typing (field is dirty).
A17: TC-EP-14 | B17: Postcode mandatory | C17: EP-PC-I2 | D17: Reject empty postcode | E17: PRE-R1 | F17: Postcode: (blank) | G17: 1. Complete PRE-R1. 2. Leave Postcode empty. 3. Click Register. | H17: Form is not submitted / account not created. Stays on Register page. Error under the field: 'Postcode is required'. | I17: P1 | J17: Major | L17: Not Run
A18: TC-EP-15 | B18: House number mandatory | C18: EP-HN-I1 | D18: Reject empty house number | E18: PRE-R1 | F18: House number: (blank) | G18: 1. Complete PRE-R1. 2. Leave House number empty. 3. Click Register. | H18: Form is not submitted / account not created. Stays on Register page. Error under the field: 'House number is required'. | I18: P2 | J18: Major | L18: Not Run
A19: TC-EP-16 | B19: Street mandatory | C19: EP-ST-I1 | D19: Reject empty street | E19: PRE-R1 | F19: Street: (blank) | G19: 1. Complete PRE-R1. 2. Leave Street empty. 3. Click Register. | H19: Form is not submitted / account not created. Stays on Register page. Error under the field: 'Street is required'. | I19: P2 | J19: Major | L19: Not Run | M19: Clear any auto-filled value first.
A20: TC-EP-17 | B20: City mandatory | C20: EP-CI-I1 | D20: Reject empty city | E20: PRE-R1 | F20: City: (blank) | G20: 1. Complete PRE-R1. 2. Leave City empty. 3. Click Register. | H20: Form is not submitted / account not created. Stays on Register page. Error under the field: 'City is required'. | I20: P2 | J20: Major | L20: Not Run | M20: Clear any auto-filled value first.
A21: TC-EP-18 | B21: State mandatory | C21: EP-SA-I1 | D21: Reject empty state | E21: PRE-R1 | F21: State: (blank) | G21: 1. Complete PRE-R1. 2. Leave State empty. 3. Click Register. | H21: Form is not submitted / account not created. Stays on Register page. Error under the field: 'State is required'. | I21: P2 | J21: Major | L21: Not Run | M21: Clear any auto-filled value first.
A22: TC-EP-19 | B22: Phone digits only | C22: EP-PH-I1 | D22: Reject phone containing letters | E22: PRE-R1 | F22: Phone: 98765abcde | G22: 1. Complete PRE-R1. 2. Phone: enter 98765abcde. 3. Click Register. | H22: Form is not submitted / account not created. Stays on Register page. Error under the field: 'Only numbers are allowed.'. | I22: P2 | J22: Major | L22: Not Run
A23: TC-EP-20 | B23: Phone digits only | C23: EP-PH-I2 | D23: Reject phone with + and spaces | E23: PRE-R1 | F23: Phone: +91 98765 43210 | G23: 1. Complete PRE-R1. 2. Phone: enter +91 98765 43210. 3. Click Register. | H23: Form is not submitted / account not created. Stays on Register page. Error under the field: 'Only numbers are allowed.'. | I23: P3 | J23: Minor | L23: Not Run | M23: Profile edit allows these characters - see Q8.
A24: TC-EP-21 | B24: Phone mandatory | C24: EP-PH-I3 | D24: Reject empty phone | E24: PRE-R1 | F24: Phone: (blank) | G24: 1. Complete PRE-R1. 2. Leave Phone empty. 3. Click Register. | H24: Form is not submitted / account not created. Stays on Register page. Error under the field: 'Phone is required.'. | I24: P1 | J24: Major | L24: Not Run | M24: Also BVA lower boundary 0.
A25: TC-EP-22 | B25: Email format | C25: EP-EM-I1 | D25: Reject email without @ | E25: PRE-R1 | F25: Email: asha.patil.example.com | G25: 1. Complete PRE-R1. 2. Email: enter asha.patil.example.com. 3. Click Register. | H25: Form is not submitted / account not created. Stays on Register page. Error under the field: 'Email format is invalid'. | I25: P1 | J25: Major | L25: Not Run
A26: TC-EP-23 | B26: Email format | C26: EP-EM-I2 | D26: Reject email containing a space | E26: PRE-R1 | F26: Email: asha patil@example.com | G26: 1. Complete PRE-R1. 2. Email: enter asha patil@example.com. 3. Click Register. | H26: Form is not submitted / account not created. Stays on Register page. Error under the field: 'Email format is invalid'. | I26: P2 | J26: Major | L26: Not Run
A27: TC-EP-24 | B27: Email uniqueness | C27: EP-EM-I3 | D27: Reject already registered email | E27: PRE-R1 | F27: Email: customer@practicesoftwaretesting.com | G27: 1. Complete PRE-R1. 2. Email: enter customer@practicesoftwaretesting.com. 3. Click Register. | H27: Account not created. Stays on Register page. Server error shown at top of form stating 'A customer with this email address already exists.'. | I27: P1 | J27: Critical | L27: Not Run
A28: TC-EP-25 | B28: Email mandatory | C28: EP-EM-I4 | D28: Reject empty email | E28: PRE-R1 | F28: Email: (blank) | G28: 1. Complete PRE-R1. 2. Leave Email empty. 3. Click Register. | H28: Form is not submitted / account not created. Stays on Register page. Error under the field: 'Email is required'. | I28: P1 | J28: Major | L28: Not Run
A29: TC-EP-26 | B29: Password composition | C29: EP-PW-I1 | D29: Reject password without uppercase | E29: PRE-R1 | F29: Password: tq7#mlpz9 | G29: 1. Complete PRE-R1. 2. Password: enter tq7#mlpz9. 3. Click Register. | H29: Form not submitted. Checklist item 'Contain both uppercase and lowercase letters' is not marked green; password error shown. | I29: P1 | J29: Major | L29: Not Run | M29: Error text is misleading - see Q5.
A30: TC-EP-27 | B30: Password composition | C30: EP-PW-I2 | D30: Reject password without lowercase | E30: PRE-R1 | F30: Password: TQ7#MLPZ9 | G30: 1. Complete PRE-R1. 2. Password: enter TQ7#MLPZ9. 3. Click Register. | H30: Form not submitted. Checklist item 'Contain both uppercase and lowercase letters' is not marked green; password error shown. | I30: P2 | J30: Major | L30: Not Run
A31: TC-EP-28 | B31: Password composition | C31: EP-PW-I3 | D31: Reject password without a digit | E31: PRE-R1 | F31: Password: Tqx#mLpzW | G31: 1. Complete PRE-R1. 2. Password: enter Tqx#mLpzW. 3. Click Register. | H31: Form not submitted. Checklist item 'Include at least one number' is not marked green; password error shown. | I31: P2 | J31: Major | L31: Not Run
A32: TC-EP-29 | B32: Password composition | C32: EP-PW-I4 | D32: Reject password without a symbol | E32: PRE-R1 | F32: Password: Tq7xmLpz9 | G32: 1. Complete PRE-R1. 2. Password: enter Tq7xmLpz9. 3. Click Register. | H32: Form not submitted. Checklist item 'Have at least one special symbol' is not marked green; password error shown. | I32: P2 | J32: Major | L32: Not Run
A33: TC-EP-30 | B33: Password not breached | C33: EP-PW-I5 | D33: Reject a known breached password | E33: PRE-R1 | F33: Password: P@ssw0rd | G33: 1. Complete PRE-R1. 2. Password: enter P@ssw0rd. 3. Click Register. | H33: Account not created. Stays on Register page. Server error shown at top of form stating the password has appeared in a data leak and a different one must be chosen. | I33: P1 | J33: Major | L33: Not Run | M33: Passes all client rules; only the server catches it.
A34: TC-EP-31 | B34: Password mandatory | C34: EP-PW-I6 | D34: Reject empty password | E34: PRE-R1 | F34: Password: (blank) | G34: 1. Complete PRE-R1. 2. Leave Password empty. 3. Click Register. | H34: Form is not submitted / account not created. Stays on Register page. Error under the field: 'Password is required'. | I34: P1 | J34: Major | L34: Not Run

Sheet BVA Analysis
A1: Boundary Value Analysis - Test Analysis (Registration)
A2: Lengths are server limits (StoreCustomer.php) unless noted. 'Reused' = boundary value already exercised by an EP case.
A3: Field | B3: Rule / range | C3: Boundary | D3: Values tested | E3: Expected | F3: Covered by
A4: First name | B4: Length 1..40 | C4: Min 0 / 1 | D4: 0 (empty) | 1 | E4: Reject | Accept | F4: TC-EP-03 (reused) | TC-BVA-01
A5: First name | B5: Length 1..40 | C5: Max 40 / 41 | D5: 40 | 41 | E5: Accept | Reject | F5: TC-BVA-02 | TC-BVA-03
A6: Last name | B6: Length 1..20 | C6: Min 0 / 1 | D6: 0 | 1 | E6: Reject | Accept | F6: TC-EP-06 (reused) | TC-BVA-04
A7: Last name | B7: Length 1..20 | C7: Max 20 / 21 | D7: 20 | 21 | E7: Accept | Reject | F7: TC-BVA-05 | TC-BVA-06
A8: Street | B8: Length max 70 | C8: Max 70 / 71 | D8: 70 | 71 | E8: Accept | Reject | F8: TC-BVA-07 | TC-BVA-08
A9: City | B9: Length max 40 | C9: Max 40 / 41 | D9: 40 | 41 | E9: Accept | Reject | F9: TC-BVA-09 | TC-BVA-10
A10: State | B10: Length max 40 | C10: Max 40 / 41 | D10: 40 | 41 | E10: Accept | Reject | F10: TC-BVA-11 | TC-BVA-12
A11: Postcode (Germany) | B11: Exactly 5 digits (^\d{5}$) | C11: Lower 4 / 5, Upper 5 / 6 | D11: 4 | 5 | 6 | E11: Reject | Accept | Reject | F11: TC-BVA-13 | TC-EP-02 (reused) | TC-BVA-14
A12: Postcode (India) | B12: No pattern; API max 10 | C12: Max 10 / 11 | D12: 10 | 11 | E12: Accept | Reject | F12: TC-BVA-15 | TC-BVA-16
A13: Phone | B13: UI: >=1 digit; API max 24 | C13: Min 0 / 1 | D13: 0 | 1 | E13: Reject | Accept | F13: TC-EP-21 (reused) | TC-BVA-17
A14: Phone | B14: API max 24 | C14: Max 24 / 25 | D14: 24 | 25 | E14: Accept | Reject | F14: TC-BVA-18 | TC-BVA-19
... A23: DOB (calendar) | B23: Month 1..12 | C23: Month 12 / 13 | D23: 1995-12-15 | 1995-13-15 | E23: Accept | Reject | F23: TC-BVA-36 | TC-BVA-37

Sheet TC - BVA
A1: Test Cases - Boundary Value Analysis - Registration
A2: Fill Actual result and Status during execution. Test data IDs (TD-xx) refer to sheet 'Test Data'.
A3: TC ID | B3: Test condition | C3: Coverage item | D3: Title | E3: Preconditions | F3: Test data | G3: Test steps | H3: Expected result | I3: Priority | J3: Severity | K3: Actual result | L3: Status | M3: Remarks
A4: TC-BVA-01 | B4: First name length | C4: Min boundary 1 | D4: Accept 1-character first name | E4: PRE-R1 | F4: First name: TD-01 | G4: 1. Complete PRE-R1. 2. First name: enter TD-01. 3. Click Register. | H4: Registration succeeds; user is redirected to the Login page (/auth/login). New account can log in. | I4: P2 | J4: Major | L4: Not Run | M4: Boundary 0 covered by TC-EP-03.
A5: TC-BVA-02 | B5: First name length | C5: Max boundary 40 | D5: Accept 40-character first name | E5: PRE-R1 | F5: First name: TD-02 | G5: 1. Complete PRE-R1. 2. First name: enter TD-02. 3. Click Register. | H5: Registration succeeds; user is redirected to the Login page (/auth/login). New account can log in. | I5: P2 | J5: Major | L5: Not Run
A6: TC-BVA-03 | B6: First name length | C6: Max+1 = 41 | D6: Reject 41-character first name | E6: PRE-R1 | F6: First name: TD-03 | G6: 1. Complete PRE-R1. 2. First name: enter TD-03. 3. Click Register. | H6: Account not created. Stays on Register page. Server error shown at top of form stating first name must not be greater than 40 characters. | I6: P2 | J6: Major | L6: Not Run | M6: No UI limit; server only.
A7: TC-BVA-04 | B7: Last name length | C7: Min boundary 1 | D7: Accept 1-character last name | E7: PRE-R1 | F7: Last name: TD-04 | G7: 1. Complete PRE-R1. 2. Last name: enter TD-04. 3. Click Register. | H7: Registration succeeds; user is redirected to the Login page (/auth/login). New account can log in. | I7: P2 | J7: Major | L7: Not Run | M7: Boundary 0 covered by TC-EP-06.
A8: TC-BVA-05 | B8: Last name length | C8: Max boundary 20 | D8: Accept 20-character last name | E8: PRE-R1 | F8: Last name: TD-05 | G8: 1. Complete PRE-R1. 2. Last name: enter TD-05. 3. Click Register. | H8: Registration succeeds; user is redirected to the Login page (/auth/login). New account can log in. | I8: P2 | J8: Major | L8: Not Run
A9: TC-BVA-06 | B9: Last name length | C9: Max+1 = 21 | D9: Reject 21-character last name | E9: PRE-R1 | F9: Last name: TD-06 | G9: 1. Complete PRE-R1. 2. Last name: enter TD-06. 3. Click Register. | H9: Account not created. Stays on Register page. Server error shown at top of form stating last name must not be greater than 20 characters. | I9: P2 | J9: Major | L9: Not Run
A10: TC-BVA-07 | B10: Street length | C10: Max boundary 70 | D10: Accept 70-character street | E10: PRE-R1 | F10: Street: TD-07 | G10: 1. Complete PRE-R1. 2. Street: enter TD-07. 3. Click Register. | H10: Registration succeeds; user is redirected to the Login page (/auth/login). New account can log in. | I10: P3 | J10: Minor | L10: Not Run
A11: TC-BVA-08 | B11: Street length | C11: Max+1 = 71 | D11: Reject 71-character street | E11: PRE-R1 | F11: Street: TD-08 | G11: 1. Complete PRE-R1. 2. Street: enter TD-08. 3. Click Register. | H11: Account not created. Stays on Register page. Server error shown at top of form stating street must not be greater than 70 characters. | I11: P3 | J11: Minor | L11: Not Run
A12: TC-BVA-09 | B12: City length | C12: Max boundary 40 | D12: Accept 40-character city | E12: PRE-R1 | F12: City: TD-09 | G12: 1. Complete PRE-R1. 2. City: enter TD-09. 3. Click Register. | H12: Registration succeeds; user is redirected to the Login page (/auth/login). New account can log in. | I12: P3 | J12: Minor | L12: Not Run
A13: TC-BVA-10 | B13: City length | C13: Max+1 = 41 | D13: Reject 41-character city | E13: PRE-R1 | F13: City: TD-10 | G13: 1. Complete PRE-R1. 2. City: enter TD-10. 3. Click Register. | H13: Account not created. Stays on Register page. Server error shown at top of form stating city must not be greater than 40 characters. | I13: P3 | J13: Minor | L13: Not Run
A14: TC-BVA-11 | B14: State length | C14: Max boundary 40 | D14: Accept 40-character state | E14: PRE-R1 | F14: State: TD-11 | G14: 1. Complete PRE-R1. 2. State: enter TD-11. 3. Click Register. | H14: Registration succeeds; user is redirected to the Login page (/auth/login). New account can log in. | I14: P3 | J14: Minor | L14: Not Run
A15: TC-BVA-12 | B15: State length | C15: Max+1 = 41 | D15: Reject 41-character state | E15: PRE-R1 | F15: State: TD-12 | G15: 1. Complete PRE-R1. 2. State: enter TD-12. 3. Click Register. | H15: Account not created. Stays on Register page. Server error shown at top of form stating state must not be greater than 40 characters. | I15: P3 | J15: Minor | L15: Not Run
A16: TC-BVA-13 | B16: Postcode length (Germany) | C16: Lower: 4 digits | D16: Reject 4-digit German postcode | E16: PRE-R1 | F16: Country: Germany; Postcode: 1011 | G16: 1. Complete PRE-R1. 2. Country / Postcode: enter Germany / 1011. 3. Click Register. | H16: Form is not submitted / account not created. Stays on Register page. Error under the field: 'Please enter a valid postal code for the selected country.'. | I16: P2 | J16: Major | L16: Not Run | M16: Boundary 5 covered by TC-EP-02.
A17: TC-BVA-14 | B17: Postcode length (Germany) | C17: Upper: 6 digits | D17: Reject 6-digit German postcode | E17: PRE-R1 | F17: Country: Germany; Postcode: 101150 | G17: 1. Complete PRE-R1. 2. Country / Postcode: enter Germany / 101150. 3. Click Register. | H17: Form is not submitted / account not created. Stays on Register page. Error under the field: 'Please enter a valid postal code for the selected country.'. | I17: P2 | J17: Major | L17: Not Run
A18: TC-BVA-15 | B18: Postcode length (no pattern) | C18: Max boundary 10 | D18: Accept 10-character Indian postcode | E18: PRE-R1 | F18: Country: India; Postcode: TD-13 | G18: 1. Complete PRE-R1. 2. Postcode: enter TD-13. 3. Click Register. | H18: Registration succeeds; user is redirected to the Login page (/auth/login). New account can log in. | I18: P3 | J18: Minor | L18: Not Run
A19: TC-BVA-16 | B19: Postcode length (no pattern) | C19: Max+1 = 11 | D19: Reject 11-character Indian postcode | E19: PRE-R1 | F19: Country: India; Postcode: TD-14 | G19: 1. Complete PRE-R1. 2. Postcode: enter TD-14. 3. Click Register. | H19: Account not created. Stays on Register page. Server error shown at top of form stating postal code must not be greater than 10 characters. | I19: P3 | J19: Minor | L19: Not Run
A20: TC-BVA-17 | B20: Phone length | C20: Min boundary 1 | D20: Accept 1-digit phone | E20: PRE-R1 | F20: Phone: 9 | G20: 1. Complete PRE-R1. 2. Phone: enter 9. 3. Click Register. | H20: Registration succeeds; user is redirected to the Login page (/auth/login). New account can log in. | I20: P3 | J20: Minor | L20: Not Run | M20: Accepting 1 digit is questionable - see Q8.
A21: TC-BVA-18 | B21: Phone length | C21: Max boundary 24 | D21: Accept 24-digit phone | E21: PRE-R1 | F21: Phone: TD-15 | G21: 1. Complete PRE-R1. 2. Phone: enter TD-15. 3. Click Register. | H21: Registration succeeds; user is redirected to the Login page (/auth/login). New account can log in. | I21: P3 | J21: Minor | L21: Not Run
A22: TC-BVA-19 | B22: Phone length | C22: Max+1 = 25 | D22: Reject 25-digit phone | E22: PRE-R1 | F22: Phone: TD-16 | G22: 1. Complete PRE-R1. 2. Phone: enter TD-16. 3. Click Register. | H22: Account not created. Stays on Register page. Server error shown at top of form stating phone must not be greater than 24 characters. | I22: P3 | J22: Minor | L22: Not Run
A23: TC-BVA-20 | B23: Email local-part length | C23: Max boundary 64 | D23: Accept email with 64-char local part | E23: PRE-R1 | F23: Email: TD-17 | G23: 1. Complete PRE-R1. 2. Email: enter TD-17. 3. Click Register. | H23: Registration succeeds; user is redirected to the Login page (/auth/login). New account can log in. | I23: P2 | J23: Major | L23: Not Run | M23: Change 'r01' in TD-17..20 each run to keep emails unique.
A24: TC-BVA-21 | B24: Email local-part length | C24: Max+1 = 65 | D24: Reject email with 65-char local part | E24: PRE-R1 | F24: Email: TD-18 | G24: 1. Complete PRE-R1. 2. Email: enter TD-18. 3. Click Register. | H24: Form is not submitted / account not created. Stays on Register page. Error under the field: 'Email format is invalid'. | I24: P2 | J24: Major | L24: Not Run
A25: TC-BVA-22 | B25: Email total length | C25: Max boundary 256 | D25: Accept 256-character email | E25: PRE-R1 | F25: Email: TD-19 | G25: 1. Complete PRE-R1. 2. Email: enter TD-19. 3. Click Register. | H25: Registration succeeds; user is redirected to the Login page (/auth/login). New account can log in. | I25: P2 | J25: Major | L25: Not Run
A26: TC-BVA-23 | B26: Email total length | C26: Max+1 = 257 | D26: Reject 257-character email | E26: PRE-R1 | F26: Email: TD-20 | G26: 1. Complete PRE-R1. 2. Email: enter TD-20. 3. Click Register. | H26: Form is not submitted / account not created. Stays on Register page. Error under the field: 'Email format is invalid'. | I26: P2 | J26: Major | L26: Not Run
A27: TC-BVA-24 | B27: Password length | C27: Min-1 = 7 | D27: Reject 7-character password | E27: PRE-R1 | F27: Password: Tq7#mLp | G27: 1. Complete PRE-R1. 2. Password: enter Tq7#mLp. 3. Click Register. | H27: Form not submitted. Checklist item 'Be at least 8 characters long' is not marked green; minimum-length error shown. | I27: P1 | J27: Major | L27: Not Run | M27: Message says 6 characters - see Q4.
A28: TC-BVA-25 | B28: Password length | C28: Min boundary 8 | D28: Accept 8-character password | E28: PRE-R1 | F28: Password: Tq7#mLpz | G28: 1. Complete PRE-R1. 2. Password: enter Tq7#mLpz. 3. Click Register. | H28: Registration succeeds; user is redirected to the Login page (/auth/login). New account can log in. | I28: P1 | J28: Major | L28: Not Run
A29: TC-BVA-26 | B29: Minimum age 18 | C29: 18y + 1 day | D29: Accept customer one day over 18 | E29: PRE-R1 | F29: DOB: TD-21 | G29: 1. Complete PRE-R1. 2. DOB: enter TD-21. 3. Click Register. | H29: Registration succeeds; user is redirected to the Login page (/auth/login). New account can log in. | I29: P1 | J29: Critical | L29: Not Run | M29: 3-value BVA.
A30: TC-BVA-27 | B30: Minimum age 18 | C30: Exactly 18 today | D30: Customer turning 18 today | E30: PRE-R1 | F30: DOB: TD-22 | G30: 1. Complete PRE-R1. 2. DOB: enter TD-22. 3. Click Register. | H30: TBC - awaiting answer to Q2. (Code rejects with 'Customer must be 18 years old.'; a literal reading of 'must be 18' would accept.) | I30: P1 | J30: Critical | L30: Not Run | M30: Do not mark Pass/Fail until Q2 is answered.
A31: TC-BVA-28 | B31: Minimum age 18 | C31: 18y - 1 day | D31: Reject customer one day short of 18 | E31: PRE-R1 | F31: DOB: TD-23 | G31: 1. Complete PRE-R1. 2. DOB: enter TD-23. 3. Click Register. | H31: Account not created. Stays on Register page. Server error shown at top of form stating 'Customer must be 18 years old.'. | I31: P1 | J31: Critical | L31: Not Run
A32: TC-BVA-29 | B32: Maximum age 75 | C32: 75y - 1 day | D32: Accept customer aged 74 years 364 days | E32: PRE-R1 | F32: DOB: TD-24 | G32: 1. Complete PRE-R1. 2. DOB: enter TD-24. 3. Click Register. | H32: Registration succeeds; user is redirected to the Login page (/auth/login). New account can log in. | I32: P2 | J32: Major | L32: Not Run | M32: 3-value BVA.
A33: TC-BVA-30 | B33: Maximum age 75 | C33: Exactly 75 today | D33: Reject customer turning 75 today | E33: PRE-R1 | F33: DOB: TD-25 | G33: 1. Complete PRE-R1. 2. DOB: enter TD-25. 3. Click Register. | H33: Account not created. Stays on Register page. Server error shown at top of form stating 'Customer must be younger than 75 years old.'. | I33: P2 | J33: Major | L33: Not Run | M33: Code review predicts FAIL - see Q3.
A34: TC-BVA-31 | B34: Maximum age 75 | C34: 75y + 1 day | D34: Reject customer one day over 75 | E34: PRE-R1 | F34: DOB: TD-26 | G34: 1. Complete PRE-R1. 2. DOB: enter TD-26. 3. Click Register. | H34: Account not created. Stays on Register page. Server error shown at top of form stating 'Customer must be younger than 75 years old.'. | I34: P2 | J34: Major | L34: Not Run | M34: Code review predicts FAIL - see Q3.
A35: TC-BVA-32 | B35: DOB calendar validity | C35: 29 Feb, leap year | D35: Accept 29 Feb in a leap year | E35: PRE-R1 | F35: DOB: 2000-02-29 | G35: 1. Complete PRE-R1. 2. DOB: enter 2000-02-29. 3. Click Register. | H35: Registration succeeds; user is redirected to the Login page (/auth/login). New account can log in. | I35: P3 | J35: Major | L35: Not Run
A36: TC-BVA-33 | B36: DOB calendar validity | C36: 29 Feb, non-leap year | D36: Reject 29 Feb in a non-leap year | E36: PRE-R1 | F36: DOB: 2001-02-29 | G36: 1. Complete PRE-R1. 2. DOB: enter 2001-02-29. 3. Click Register. | H36: Form is not submitted / account not created. Stays on Register page. Error under the field: 'Please enter a valid date in YYYY-MM-DD format.'. | I36: P3 | J36: Major | L36: Not Run
A37: TC-BVA-34 | B37: DOB calendar validity | C37: Day 30 of April | D37: Accept last day of a 30-day month | E37: PRE-R1 | F37: DOB: 1995-04-30 | G37: 1. Complete PRE-R1. 2. DOB: enter 1995-04-30. 3. Click Register. | H37: Registration succeeds; user is redirected to the Login page (/auth/login). New account can log in. | I37: P3 | J37: Minor | L37: Not Run
A38: TC-BVA-35 | B38: DOB calendar validity | C38: Day 31 of April | D38: Reject day 31 in a 30-day month | E38: PRE-R1 | F38: DOB: 1995-04-31 | G38: 1. Complete PRE-R1. 2. DOB: enter 1995-04-31. 3. Click Register. | H38: Form is not submitted / account not created. Stays on Register page. Error under the field: 'Please enter a valid date in YYYY-MM-DD format.'. | I38: P3 | J38: Minor | L38: Not Run
A39: TC-BVA-36 | B39: DOB calendar validity | C39: Month 12 | D39: Accept month 12 | E39: PRE-R1 | F39: DOB: 1995-12-15 | G39: 1. Complete PRE-R1. 2. DOB: enter 1995-12-15. 3. Click Register. | H39: Registration succeeds; user is redirected to the Login page (/auth/login). New account can log in. | I39: P3 | J39: Minor | L39: Not Run
A40: TC-BVA-37 | B40: DOB calendar validity | C40: Month 13 | D40: Reject month 13 | E40: PRE-R1 | F40: DOB: 1995-13-15 | G40: 1. Complete PRE-R1. 2. DOB: enter 1995-13-15. 3. Click Register. | H40: Form is not submitted / account not created. Stays on Register page. Error under the field: 'Please enter a valid date in YYYY-MM-DD format.'. | I40: P3 | J40: Minor | L40: Not Run

Sheet STT Model
A1: State Transition Model - Login (failed-attempt counter, lockout, TOTP, disabled account)
A2: Source: UserService::login(), MAX_LOGIN_ATTEMPTS = 3. Admin accounts are exempt from the counter (guard).
A3: State | B3: Description | C3: Note
A4: S0 | B4: Logged out, failed attempts = 0 | C4: Initial state
A5: S1 | B5: Logged out, failed attempts = 1
A6: S2 | B6: Logged out, failed attempts = 2
A7: S3 | B7: Locked, failed attempts = 3 | C7: Only admin can unlock
A8: S4 | B8: Logged in (customer) - My Account
A9: S5 | B9: TOTP challenge pending | C9: Only for users with TOTP enabled
A10: S6 | B10: Disabled account | C10: Set by admin ('Enabled' unticked)
A12: Event | B12: Description
A13: E1 | B13: Submit registered email + correct password
A14: E2 | B14: Submit registered email + wrong password
A15: E3 | B15: Submit unregistered email (any password)
A16: E4 | B16: Submit with client-side error (empty field, bad email format, password < 3 chars)
A17: E5 | B17: Logout
A18: E6 | B18: Admin sets 'Failed login attempts' = 0
A19: E7 | B19: Enter valid TOTP code
A20: E8 | B20: Enter invalid TOTP code
A22: State table (rows = current state, columns = event; cell = next state / visible output; '-' = event not possible in that state)
A23: State | B23: E1 | C23: E2 | D23: E3 | E23: E4 | F23: E5 | G23: E6 | H23: E7 / E8
A24: S0 | B24: S4 (S5 if TOTP on) | C24: S1 / 'Invalid email or password' | D24: S0 / same message | E24: S0 / field error, no request | F24: - | G24: S0 | H24: -
A25: S1 | B25: S4 / counter reset to 0 | C25: S2 / 'Invalid email or password' | D25: - | E25: S1 / field error | F25: - | G25: S0 | H25: -
A26: S2 | B26: S4 / counter reset to 0 | C26: S3 / 'Invalid email or password' | D26: - | E26: S2 / field error | F26: - | G26: S0 | H26: -
A27: S3 | B27: S3 / 'Account locked...' (rejected) | C27: S3 / 'Account locked...' | D27: - | E27: S3 / field error | F27: - | G27: S0 | H27: -
A28: S4 | B28: - | C28: - | D28: - | E28: - | F28: S0 | G28: - | H28: -
A29: S5 | B29: - | C29: - | D29: - | E29: - | F29: - | G29: - | H29: E7: S4 | E8: S5 / 'Invalid TOTP'
A30: S6 | B30: S6 / 'Account disabled' | C30: S6 / 'Invalid email or password' | D30: - | E30: S6 / field error | F30: - | G30: - | H30: -
A32: Transition list (coverage items)
A33: Trans. ID | B33: From | C33: Event | D33: Guard | E33: To | F33: Output | G33: Type | H33: Covered by
A34: T01 | B34: S0 | C34: E1 | D34: TOTP off | E34: S4 | F34: Redirect to /account | G34: Valid | H34: TC-STT-01
A35: T02 | B35: S0 | C35: E1 | D35: TOTP on | E35: S5 | F35: TOTP field shown | G35: Valid | H35: TC-STT-14
A36: T03 | B36: S0 | C36: E2 | E36: S1 | F36: 'Invalid email or password' | G36: Valid | H36: TC-STT-03
A37: T04 | B37: S0 | C37: E3 | E37: S0 | F37: 'Invalid email or password' | G37: Valid | H37: TC-STT-12
A38: T05 | B38: S1 | C38: E4 | E38: S1 | F38: Field error, counter unchanged | G38: Valid | H38: TC-STT-13
A39: T06 | B39: S1 | C39: E1 | E39: S4 | F39: Counter reset | G39: Valid | H39: TC-STT-04, TC-STT-11
A40: T07 | B40: S1 | C40: E2 | E40: S2 | F40: 'Invalid email or password' | G40: Valid | H40: TC-STT-05
A41: T08 | B41: S2 | C41: E1 | E41: S4 | F41: Counter reset | G41: Valid | H41: TC-STT-06, TC-STT-11
A42: T09 | B42: S2 | C42: E2 | D42: Not admin | E42: S3 | F42: 'Invalid email or password' | G42: Valid | H42: TC-STT-07
A43: T10 | B43: S3 | C43: E1 | E43: S3 | F43: 'Account locked...' | G43: Invalid (event rejected) | H43: TC-STT-08
...

Sheet TC - STT
A1: Test Cases - State Transition Testing - Login
A2: Fill Actual result and Status during execution. Test data IDs (TD-xx) refer to sheet 'Test Data'.
A3: TC ID | B3: Test condition | C3: Coverage item | D3: Title | E3: Preconditions | F3: Test data | G3: Test steps | H3: Expected result | I3: Priority | J3: Severity | K3: Actual result | L3: Status | M3: Remarks
A4: TC-STT-01 | B4: Successful login | C4: T01 (S0-E1-S4) | D4: Log in with valid credentials | E4: PRE-L1 (state S0) | F4: Own email + password | G4: 1. Enter email and correct password. 2. Click Login. | H4: Redirected to /account (My Account); user name shown in navigation. | I4: P1 | J4: Critical | L4: Not Run
A5: TC-STT-02 | B5: Logout | C5: T13 (S4-E5-S0) | D5: Log out from My Account | E5: Logged in (state S4) | F5: - | G5: 1. Open the user menu and click Sign out. 2. Enter /account in the address bar. | H5: Step 1: user is logged out, Sign in link shown. Step 2: My Account is not shown; user is sent to login. | I5: P1 | J5: Critical | L5: Not Run
A6: TC-STT-03 | B6: First failed attempt | C6: T03 (S0-E2-S1) | D6: One wrong password from S0 | E6: PRE-L1 (state S0) | F6: Password: Wrong#123x | G6: 1. Enter email and wrong password. 2. Click Login. | H6: Error 'Invalid email or password'; stays on login page; not logged in. | I6: P1 | J6: Major | L6: Not Run
A7: TC-STT-04 | B7: Login after 1 failure | C7: T06 (S1-E1-S4) | D7: Correct password after one failure | E7: PRE-L1 + 1 failed login (state S1) | F7: Correct password | G7: 1. Enter email and correct password. 2. Click Login. | H7: Redirected to /account; counter reset to 0 (verified in TC-STT-11). | I7: P1 | J7: Critical | L7: Not Run
A8: TC-STT-05 | B8: Second failed attempt | C8: T07 (S1-E2-S2) | D8: Second consecutive wrong password | E8: PRE-L1 + 1 failed login (state S1) | F8: Password: Wrong#123x | G8: 1. Enter email and wrong password. 2. Click Login. | H8: Error 'Invalid email or password'; not logged in; account not locked. | I8: P1 | J8: Major | L8: Not Run
A9: TC-STT-06 | B9: Login after 2 failures | C9: T08 (S2-E1-S4) | D9: Correct password after two failures | E9: PRE-L1 + 2 failed logins (state S2) | F9: Correct password | G9: 1. Enter email and correct password. 2. Click Login. | H9: Redirected to /account. | I9: P1 | J9: Critical | L9: Not Run
A10: TC-STT-07 | B10: Lock on 3rd failure | C10: T09 (S2-E2-S3) | D10: Third consecutive wrong password locks account | E10: PRE-L1 + 2 failed logins (state S2) | F10: Password: Wrong#123x | G10: 1. Enter email and wrong password. 2. Click Login. | H10: Error 'Invalid email or password'; not logged in. Account is now locked (confirm by running TC-STT-08 immediately). | I10: P1 | J10: Critical | L10: Not Run | M10: No lock message on the 3rd attempt - see Q9.
A11: TC-STT-08 | B11: Locked rejects correct password | C11: T10 (S3-E1-S3) invalid | D11: Correct password on a locked account | E11: Account locked (state S3, after TC-STT-07) | F11: Correct password | G11: 1. Enter email and correct password. 2. Click Login. | H11: Error 'Account locked, too many failed attempts. Please contact the administrator.' Not logged in. | I11: P1 | J11: Critical | L11: Not Run | M11: Key security case.
A12: TC-STT-09 | B12: Locked rejects wrong password | C12: T11 (S3-E2-S3) invalid | D12: Wrong password on a locked account | E12: Account locked (state S3) | F12: Password: Wrong#123x | G12: 1. Enter email and wrong password. 2. Click Login. | H12: Error 'Account locked, too many failed attempts. Please contact the administrator.' Not logged in. | I12: P2 | J12: Major | L12: Not Run
A13: TC-STT-10 | B13: Admin unlock | C13: T12 (S3-E6-S0), then T01 | D13: Login works after admin unlock | E13: Account locked (state S3) | F13: Correct password | G13: 1. Complete PRE-ADMIN: set Failed login attempts = 0. 2. As the customer, enter email and correct password. 3. Click Login. | H13: Step 3: redirected to /account. | I13: P1 | J13: Major | L13: Not Run
A14: TC-STT-11 | B14: Counter resets after success | C14: T07, T08, T13, T03, T07, T08 (1-switch) | D14: Successful login resets the failed-attempt counter | E14: PRE-L1 (state S0) | F14: Wrong: Wrong#123x; then correct | G14: 1. Wrong password twice (S2). 2. Correct password (S4). 3. Log out (S0). 4. Wrong password twice (S2). 5. Correct password. | H14: Step 5: redirected to /account (not locked). If the counter did not reset, step 4 would already lock the account. | I14: P1 | J14: Critical | L14: Not Run
A15: TC-STT-12 | B15: Unknown email | C15: T04 (S0-E3-S0) | D15: Login with an unregistered email | E15: Logged out on /auth/login | F15: Email: not.registered.<run>@example.com; any password | G15: 1. Enter unregistered email and any password. 2. Click Login. | H15: Error 'Invalid email or password' - identical to a wrong password, so the response does not reveal whether the email exists. | I15: P2 | J15: Major | L15: Not Run
A16: TC-STT-13 | B16: Client-side errors do not count | C16: T05 (S1-E4-S1), then T07, T08 | D16: Validation errors are not counted as failed attempts | E16: PRE-L1 + 1 failed login (state S1) | F16: Email: abc (bad format); then wrong; then correct | G16: 1. Enter email 'abc' and any password; click Login. 2. Enter valid email + wrong password; click Login. 3. Enter correct password; click Login. | H16: Step 1: 'Email format is invalid', no request sent. Step 2: 'Invalid email or password'. Step 3: redirected to /account (not locked, so step 1 was not counted). | I16: P2 | J16: Major | L16: Not Run
A17: TC-STT-14 | B17: TOTP challenge | C17: T02 (S0-E1-S5) | D17: TOTP user is asked for a code | E17: PRE-L1 with TOTP enabled in My Account > Profile (state S0) | F17: Correct password | G17: 1. Enter email and correct password. 2. Click Login. | H17: TOTP code field and Verify button shown; user not yet logged in. | I17: P3 | J17: Major | L17: Not Run
A18: TC-STT-15 | B18: Invalid TOTP | C18: T14 (S5-E8-S5) | D18: Wrong TOTP code keeps the challenge open | E18: TOTP challenge shown (state S5) | F18: TOTP: 000000 | G18: 1. Enter 000000. 2. Click Verify. | H18: Error 'Invalid TOTP'; still on TOTP step; not logged in. | I18: P3 | J18: Major | L18: Not Run | M18: Effect on lock counter unspecified - see Q10.
A19: TC-STT-16 | B19: Valid TOTP | C19: T15 (S5-E7-S4) | D19: Correct TOTP code completes login | E19: TOTP challenge shown (state S5) | F19: Current code from authenticator app | G19: 1. Enter current code. 2. Click Verify. | H19: Redirected to /account. | I19: P3 | J19: Critical | L19: Not Run
A20: TC-STT-17 | B20: Disabled account | C20: T16 (S6-E1-S6) invalid | D20: Correct password on a disabled account | E20: PRE-L1; admin unticks 'Enabled' via PRE-ADMIN (state S6) | F20: Correct password | G20: 1. Enter email and correct password. 2. Click Login. | H20: Error 'Account disabled'; not logged in. | I20: P2 | J20: Major | L20: Not Run
A21: TC-STT-18 | B21: Admin exempt from lockout | C21: T17 guard [admin] | D21: Admin is not locked after repeated failures | E21: LOCAL instance only. Admin logged out. | F21: admin@practicesoftwaretesting.com; Wrong#123x x4; then welcome01 | G21: 1. Wrong password 4 times. 2. Correct password. | H21: Step 1: 'Invalid email or password' every time, never the lock message. Step 2: redirected to admin dashboard. | I21: P3 | J21: Major | L21: Not Run | M21: LOCAL only - do not hammer the shared demo admin.
A22: TC-STT-19 | B22: Counter reset for TOTP users | C22: T18 (S2-E1-S5-E7-S4), then T03 | D22: Successful TOTP login resets the counter | E22: PRE-L1 with TOTP enabled + 2 failed logins (state S2) | F22: Correct password + valid TOTP; then Wrong#123x; then correct | G22: 1. Correct password, then valid TOTP (S4). 2. Log out. 3. Wrong password once. 4. Correct password. | H22: Step 4: TOTP challenge shown (account not locked). | I22: P3 | J22: Critical | L22: Not Run | M22: Code review predicts FAIL ('Account locked') - see Q10.

Sheet Test Data
A1: Test Data - generated values (formulas recalculate on open; copy the 'Value' cell when executing)
A3: TD ID | B3: Field | C3: Description | D3: Value | E3: Actual length | F3: Expected length | G3: Length check
A4: TD-01 | B4: First name | C4: 1 character | D4: A | E4: =LEN(D4) -> 1 | F4: 1 | G4: =IF(E4=F4,"OK","CHECK") -> OK
A5: TD-02 | B5: First name | C5: 40 characters (max) | D5: =REPT("A",40) -> AAAAAAAAAAAAAAAAAAAAAAAAAAAAAAAAAAAAAAAA | E5: =LEN(D5) -> 40 | F5: 40 | G5: =IF(E5=F5,"OK","CHECK") -> OK
A6: TD-03 | B6: First name | C6: 41 characters (max+1) | D6: =REPT("A",41) -> AAAAAAAAAAAAAAAAAAAAAAAAAAAAAAAAAAAAAAAAA | E6: =LEN(D6) -> 41 | F6: 41 | G6: =IF(E6=F6,"OK","CHECK") -> OK
A7: TD-04 | B7: Last name | C7: 1 character | D7: P | E7: =LEN(D7) -> 1 | F7: 1 | G7: =IF(E7=F7,"OK","CHECK") -> OK
A8: TD-05 | B8: Last name | C8: 20 characters (max) | D8: =REPT("P",20) -> PPPPPPPPPPPPPPPPPPPP | E8: =LEN(D8) -> 20 | F8: 20 | G8: =IF(E8=F8,"OK","CHECK") -> OK
A9: TD-06 | B9: Last name | C9: 21 characters (max+1) | D9: =REPT("P",21) -> PPPPPPPPPPPPPPPPPPPPP | E9: =LEN(D9) -> 21 | F9: 21 | G9: =IF(E9=F9,"OK","CHECK") -> OK
A10: TD-07 | B10: Street | C10: 70 characters (max) | D10: =REPT("S",70) -> SSSSSSSSSSSSSSSSSSSSSSSSSSSSSSSSSSSSSSSSSSSSSSSSSSSSSSSSSSSSSSSSSSSSSS | E10: =LEN(D10) -> 70 | F10: 70 | G10: =IF(E10=F10,"OK","CHECK") -> OK
A11: TD-08 | B11: Street | C11: 71 characters (max+1) | D11: =REPT("S",71) -> SSSSSSSSSSSSSSSSSSSSSSSSSSSSSSSSSSSSSSSSSSSSSSSSSSSSSSSSSSSSSSSSSSSSSSS | E11: =LEN(D11) -> 71 | F11: 71 | G11: =IF(E11=F11,"OK","CHECK") -> OK
A12: TD-09 | B12: City | C12: 40 characters (max) | D12: =REPT("C",40) -> CCCCCCCCCCCCCCCCCCCCCCCCCCCCCCCCCCCCCCCC | E12: =LEN(D12) -> 40 | F12: 40 | G12: =IF(E12=F12,"OK","CHECK") -> OK
A13: TD-10 | B13: City | C13: 41 characters (max+1) | D13: =REPT("C",41) -> CCCCCCCCCCCCCCCCCCCCCCCCCCCCCCCCCCCCCCCCC | E13: =LEN(D13) -> 41 | F13: 41 | G13: =IF(E13=F13,"OK","CHECK") -> OK
A14: TD-11 | B14: State | C14: 40 characters (max) | D14: =REPT("T",40) -> TTTTTTTTTTTTTTTTTTTTTTTTTTTTTTTTTTTTTTTT | E14: =LEN(D14) -> 40 | F14: 40 | G14: =IF(E14=F14,"OK","CHECK") -> OK
A15: TD-12 | B15: State | C15: 41 characters (max+1) | D15: =REPT("T",41) -> TTTTTTTTTTTTTTTTTTTTTTTTTTTTTTTTTTTTTTTTT | E15: =LEN(D15) -> 41 | F15: 41 | G15: =IF(E15=F15,"OK","CHECK") -> OK
A16: TD-13 | B16: Postcode (India) | C16: 10 characters (API max) | D16: 4110181234 | E16: =LEN(D16) -> 10 | F16: 10 | G16: =IF(E16=F16,"OK","CHECK") -> OK
A17: TD-14 | B17: Postcode (India) | C17: 11 characters (max+1) | D17: 41101812345 | E17: =LEN(D17) -> 11 | F17: 11 | G17: =IF(E17=F17,"OK","CHECK") -> OK
A18: TD-15 | B18: Phone | C18: 24 digits (API max) | D18: =REPT("9",24) -> 999999999999999999999999 | E18: =LEN(D18) -> 24 | F18: 24 | G18: =IF(E18=F18,"OK","CHECK") -> OK
A19: TD-16 | B19: Phone | C19: 25 digits (max+1) | D19: =REPT("9",25) -> 9999999999999999999999999 | E19: =LEN(D19) -> 25 | F19: 25 | G19: =IF(E19=F19,"OK","CHECK") -> OK
A20: TD-17 | B20: Email | C20: local part 64 chars (max); total 76 | D20: =REPT("q",61)&"r01@example.com" -> qqqqqqqqqqqqqqqqqqqqqqqqqqqqqqqqqqqqqqqqqqqqqqqqqqqqqqqqqqqqqr01@example.com | E20: =LEN(D20) -> 76 | F20: 76 | G20: =IF(E20=F20,"OK","CHECK") -> OK
A21: TD-18 | B21: Email | C21: local part 65 chars (max+1) | D21: =REPT("q",62)&"r01@example.com" -> qqqqqqqqqqqqqqqqqqqqqqqqqqqqqqqqqqqqqqqqqqqqqqqqqqqqqqqqqqqqqqr01@example.com | E21: =LEN(D21) -> 77 | F21: 77 | G21: =IF(E21=F21,"OK","CHECK") -> OK
A22: TD-19 | B22: Email | C22: total length 256 (max) | D22: =REPT("q",61)&"r01@"&REPT("d",63)&"."&REPT("d",63)&"."&REPT("d",59)&".com" -> qqqqqqqqqqqqqqqqqqqqqqqqqqqqqqqqqqqqqqqqqqqqqqqqqqqqqqqqqqqqqr01@ddddddddddddddddddddddddddddddddddddddddddddddddddddddddddddddd.ddddddddddddddddddddddddddddddddddddddddddddddddddddddddddddddd.ddddddddddddddddddddddddddddddddddddddddddddddddddddddddddd.com | E22: =LEN(D22) -> 256 | F22: 256 | G22: =IF(E22=F22,"OK","CHECK") -> OK
A23: TD-20 | B23: Email | C23: total length 257 (max+1) | D23: =REPT("q",61)&"r01@"&REPT("d",63)&"."&REPT("d",63)&"."&REPT("d",60)&".com" -> qqqqqqqqqqqqqqqqqqqqqqqqqqqqqqqqqqqqqqqqqqqqqqqqqqqqqqqqqqqqqr01@ddddddddddddddddddddddddddddddddddddddddddddddddddddddddddddddd.ddddddddddddddddddddddddddddddddddddddddddddddddddddddddddddddd.dddddddddddddddddddddddddddddddddddddddddddddddddddddddddddd.com | E23: =LEN(D23) -> 257 | F23: 257 | G23: =IF(E23=F23,"OK","CHECK") -> OK
A24: TD-21 | B24: DOB | C24: Age 18 years + 1 day (today - 18y - 1d) | D24: =TEXT(EDATE(TODAY(),-216)-1,"yyyy-mm-dd") -> 2008-10-07 | E24: =LEN(D24) -> 10 | F24: 10 | G24: =IF(E24=F24,"OK","CHECK") -> OK
A25: TD-22 | B25: DOB | C25: Exactly 18 today (today - 18y) | D25: =TEXT(EDATE(TODAY(),-216),"yyyy-mm-dd") -> 2008-10-08 | E25: =LEN(D25) -> 10 | F25: 10 | G25: =IF(E25=F25,"OK","CHECK") -> OK
A26: TD-23 | B26: DOB | C26: 1 day short of 18 (today - 18y + 1d) | D26: =TEXT(EDATE(TODAY(),-216)+1,"yyyy-mm-dd") -> 2008-10-09 | E26: =LEN(D26) -> 10 | F26: 10 | G26: =IF(E26=F26,"OK","CHECK") -> OK
A27: TD-24 | B27: DOB | C27: 74 years 364 days (today - 75y + 1d) | D27: =TEXT(EDATE(TODAY(),-900)+1,"yyyy-mm-dd") -> 1951-10-09 | E27: =LEN(D27) -> 10 | F27: 10 | G27: =IF(E27=F27,"OK","CHECK") -> OK
A28: TD-25 | B28: DOB | C28: Exactly 75 today (today - 75y) | D28: =TEXT(EDATE(TODAY(),-900),"yyyy-mm-dd") -> 1951-10-08 | E28: =LEN(D28) -> 10 | F28: 10 | G28: =IF(E28=F28,"OK","CHECK") -> OK
A29: TD-26 | B29: DOB | C29: 75 years + 1 day (today - 75y - 1d) | D29: =TEXT(EDATE(TODAY(),-900)-1,"yyyy-mm-dd") -> 1951-10-07 | E29: =LEN(D29) -> 10 | F29: 10 | G29: =IF(E29=F29,"OK","CHECK") -> OK
A30: TD-27 | B30: DOB | C30: EP: age 10 (under-18 partition) | D30: =TEXT(EDATE(TODAY(),-120),"yyyy-mm-dd") -> 2016-10-08 | E30: =LEN(D30) -> 10 | F30: 10 | G30: =IF(E30=F30,"OK","CHECK") -> OK
A31: TD-28 | B31: DOB | C31: EP: age 80 (75+ partition) | D31: =TEXT(EDATE(TODAY(),-960),"yyyy-mm-dd") -> 1946-10-08 | E31: =LEN(D31) -> 10 | F31: 10 | G31: =IF(E31=F31,"OK","CHECK") -> OK
